<?xml version="1.0" ?>

<robot name="robot_with_sensors" xmlns:xacro="https://www.ros.org/wiki/xacro" >
    
  <xacro:include filename="$(find challenge_project)/urdf/robot_with_sensors_materials.xacro" />
  <xacro:include filename="$(find challenge_project)/urdf/robot_with_sensors.gazebo" />

  <!-- ========================== Chassis definition ======================== -->
  <link name="link_chassis">
    
    <pose>0 0 0.0175 0 0 0</pose>
    
    <!-- %%%%%%%%%%%%%%%%%%%%%%%% Chassis definition %%%%%%%%%%%%%%%%%%%%%%%% -->
    <visual>
      <origin rpy="0 0 0" xyz="0 0 0"/>
      <geometry>
        <box size="0.136 0.136 0.009"/>
      </geometry>
      <material name="blue"/>
    </visual>
    
    <collision name="collision_chassis">
      <geometry>
        <box size="0.136 0.136 0.009"/>
      </geometry>
    </collision>

    <inertial name="inertial_chassis">
      <mass value="0.150"/>
      <origin rpy="0 0 0" xyz="0 0 0"/>
      <inertia ixx="0.00033245" ixy="0" ixz="0" iyy="0.00033245" iyz="0" izz="0.0004624"/>
    </inertial>
    
    <!-- %%%%%%%%%%%%%%%%%%%%%%%% Motor on the left %%%%%%%%%%%%%%%%%%%%%%%% -->
    <visual>
      <origin rpy="0 0 0" xyz="-0.058 -0.035 0.0155"/>
      <geometry>
        <box size="0.020 0.030 0.022"/>
      </geometry>
      <material name="blue"/>
    </visual>

    <collision name="collision_motor_left">
      <origin rpy="0 0 0" xyz="-0.058 -0.035 0.0155"/>
      <geometry>
        <box size="0.020 0.030 0.022"/>
      </geometry>
    </collision>

    <inertial name="inertial_motor_left">
      <mass value="0.082"/>
      <origin rpy="0 0 0" xyz="0 0 0"/>
      <inertia ixx="0.000009457" ixy="0" ixz="0" iyy="0.000006041" iyz="0" izz="0.000008883"/>
    </inertial>

    <!-- %%%%%%%%%%%%%%%%%%%%%%%% Motor on the right %%%%%%%%%%%%%%%%%%%%%%%% -->
    <visual>
      <origin rpy="0 0 0" xyz="0.058 -0.035 0.0155"/>
      <geometry>
        <box size="0.020 0.030 0.022"/>
      </geometry>
      <material name="blue"/>
    </visual>

    <collision name="collision_motor_right">
      <origin rpy="0 0 0" xyz="0.058 -0.035 0.0155"/>
      <geometry>
        <box size="0.020 0.030 0.022"/>
      </geometry>
    </collision>

    <inertial name="inertial_motor_right">
      <mass value="0.082"/>
      <origin rpy="0 0 0" xyz="0 0 0"/>
      <inertia ixx="0.000009457" ixy="0" ixz="0" iyy="0.000006041" iyz="0" izz="0.000008883"/>
    </inertial>

    <!-- %%%%%%%%%%%%%%%%%%%%%%%% Caster %%%%%%%%%%%%%%%%%%%%%%%% -->
    <visual>
      <origin rpy=" 0 0 0" xyz="0 0.047 -0.0045"/>
      <geometry>
        <sphere radius="0.013"/>
      </geometry>
      <material name="blue"/>
    </visual>

    <collision name="collision_caster">
      <origin rpy=" 0 0 0" xyz="0 0.047 -0.0045"/>
      <geometry>
        <sphere radius="0.013"/>
      </geometry>
      <surface>
        <friction>
          <ode>
            <mu>0</mu>
            <mu2>0</mu2>
            <slip1>1.0</slip1>
            <slip2>1.0</slip2>
          </ode>
        </friction>
      </surface>
    </collision>
  
    <!-- %%%%%%%%%%%%%%%%%%%%%%%% LASER support %%%%%%%%%%%%%%%%%%%%% -->
    <visual>
      <origin rpy="0 0 0" xyz="0 0 0.0295"/>
      <geometry>
        <cylinder length="0.05" radius="0.02"/>
      </geometry>
      <material name="green"/>
    </visual>

    <collision name="collision_lds_chassis">
      <origin rpy="0 0 0" xyz="0 0 0.0295"/>
      <geometry>
        <cylinder length="0.05" radius="0.02"/>
      </geometry>
    </collision>

  </link>
  
  <!-- ======================= Right wheel definition =================== -->   
  <link name="link_right_wheel">    
        
    <visual>
      <origin rpy="0 1.5707 0" xyz="0 0 0"/>
      <geometry>
        <cylinder length="0.018" radius="0.033"/>
      </geometry> 
      <material name="red"/>
    </visual>
    
    <collision name="collision_right_wheel">
      <origin rpy="0 1.5707 0" xyz="0 0 0"/>
      <geometry>
        <cylinder length="0.018" radius="0.033"/>
      </geometry> 
    </collision>

    <inertial name="inertial_right_wheel">
      <mass value="0.120"/>
      <origin rpy="0 1.5707 0" xyz="0 0 0"/>
      <inertia ixx="0.03109224" ixy="0" ixz="0" iyy="0.03109224" iyz="0" izz="0.00006534"/>
    </inertial>

  </link>

  <!-- %%%%%%%%%  Joint for right wheel  %%%%%%%%% -->
  <joint name="joint_right_wheel" type="continuous">
    <origin rpy="0 0 0" xyz="-0.077 -0.035 0.0155"/>
    <child link="link_right_wheel" />
    <parent link="link_chassis"/>
    <axis rpy="0 0 0" xyz="1 0 0"/>
    <limit effort="10000" velocity="1000"/>
    <joint_properties damping="1.0" friction="1.0" />
  </joint>  

  <!-- ======================= Left wheel definition =================== -->     
  <link name="link_left_wheel">    
        
    <visual>
      <origin rpy="0 1.5707 0" xyz="0 0 0"/>
      <geometry>
        <cylinder length="0.018" radius="0.033"/>
      </geometry> 
      <material name="red"/>
    </visual>
    
    <collision name="collision_left_wheel">
      <origin rpy="0 1.5707 0" xyz="0 0 0"/>
      <geometry>
        <cylinder length="0.018" radius="0.033"/>
      </geometry> 
    </collision>

    <inertial name="inertial_left_wheel">
      <mass value="0.120"/>
      <origin rpy="0 1.5707 0" xyz="0 0 0"/>
      <inertia ixx="0.03109224" ixy="0" ixz="0" iyy="0.03109224" iyz="0" izz="0.00006534"/>
    </inertial>
  </link>

  <!-- %%%%%%%%%  Joint for left wheel  %%%%%%%%% -->
  <joint name="joint_left_wheel" type="continuous">
    <origin rpy="0 0 0" xyz="0.077 -0.035 0.0155"/>
    <child link="link_left_wheel" />
    <parent link="link_chassis"/>
    <axis rpy="0 0 0" xyz="1 0 0"/>
    <limit effort="10000" velocity="1000"/>
    <joint_properties damping="1.0" friction="1.0" />
  </joint>  

  <!-- ======================= Camera definition =================== -->     
  <link name="link_camera">
    
    <visual>
      <origin xyz="0 0 0" rpy="0 0 0"/>
      <geometry>
        <box size="0.015 0.015 0.015"/>
      </geometry>
      <material name="green"/>
    </visual>

    <collision name="collision_camera">
      <origin xyz="0 0 0" rpy="0 0 0"/>
      <geometry>
        <box size="0.015 0.015 0.015"/>
      </geometry>
      <material name="green"/>
    </collision>

    <inertial name="inertial_camera">
      <mass value="0.020"/>
      <origin rpy="0 0 0" xyz="0 0 0"/>
      <inertia ixx="0.00000075" ixy="0" ixz="0" iyy="0.00000075" iyz="0" izz="0.00000075"/>
    </inertial>

  </link>

  <!-- %%%%%%%%% Joint for camera %%%%%%%%% -->
  <joint name="joint_camera" type="fixed">
    <axis xyz="0 1 0" />
    <origin xyz="0 -0.0605 0.012" rpy="0 0 -1.5707"/>
    <parent link="link_chassis"/>
    <child link="link_camera"/>
  </joint>

  <!-- ==================== LDS definition ======================== -->
  <link name="link_lds">
    
    <visual>
      <origin rpy="0 0 0" xyz="0 0 0"/>
      <geometry>
        <sphere radius="0.02"/>
      </geometry>
      <material name="green"/>
    </visual>

    <collision name="collision_lds2">
      <origin rpy="0 0 0" xyz="0 0 0"/>
      <geometry>
        <sphere radius="0.02"/>
      </geometry>
    </collision>

  </link>

  <!-- %%%%%%%%% Joint for LDS %%%%%%%%%%%%%%%%% -->
  <joint name="joint_lds" type="fixed">
    <axis xyz="0 0 0"/>
    <origin xyz="0 0 0.0545" rpy="0 0 4.712"/>
    <parent link="link_chassis"/>
    <child link="link_lds"/>
  </joint>

</robot>